Workbook
Name ACTION: #REF!
Name ACTION: #REF!

Sheet Cover
B2: TEST REPORT DOCUMENT
A4: Project Name | B4: Developing TikoSmart – a frozen food warehouse management system for TIKOVIA Trading and Service Co., Ltd. using ReactJS, React Native and NodeJS. | E4: Creator
A5: Project Code | B5: TSW | E5: Issue Date | F5: 46090
A6: Document Code | B6: =B5&"_"&"Test Report"&"_"&"v1.0" -> TSW_Test Report_v1.0 | E6: Version | F6: 1
A9: Record of change
A10: Effective Date | B10: Version | C10: Change Item | D10: *A,D,M | E10: Change description | F10: Reference
A11: 46090 | B11: 1.0 | C11: Initial Draft | D11: A | E11: Created the initial test document.
A12: 46091 | B12: 1.1 | C12: New Section | D12: M | E12: Add test case to document

Sheet Test Statistics
B1: TEST STATISTICS
B3: Project Name | C3: Developing VALOParking – A smart vehicle automated location organizer using ReactJS, NodeJS, AI YOLOv11 and IoT ESP32. | E3: Creator
B4: Project Code | C4: VALO | E4: Reviewer/Approver
B5: Document Code | C5: =C4&"_"&"Test Report"&"_"&"v1.0" -> VALO_Test Report_v1.0 | E5: Issue Date | H5: =Cover!F5 -> 46090
B6: Notes
B10: No | C10: Module code | D10: Passed | E10: Failed | F10: Pending | G10: N/A | H10: Number of test cases
B11: 1 | C11: Kiosk Check-in & Check-out | D11: ='1. Kiosk Check-in & Check-out'!B6 -> 19 | E11: ='1. Kiosk Check-in & Check-out'!C6 -> 7 | F11: ='1. Kiosk Check-in & Check-out'!D6 -> 0 | G11: ='1. Kiosk Check-in & Check-out'!E6 -> 0 | H11: ='1. Kiosk Check-in & Check-out'!B4 -> 26
B12: 2 | C12: Staff Gate & Barrier Control | D12: ='2. Staff Gate & Barrier Control'!B6 -> 17 | E12: ='2. Staff Gate & Barrier Control'!C6 -> 0 | F12: ='2. Staff Gate & Barrier Control'!D6 -> 0 | G12: ='2. Staff Gate & Barrier Control'!E6 -> 0 | H12: ='2. Staff Gate & Barrier Control'!B4 -> 17
B13: 3 | C13: IoT Barrier Integration | D13: ='3. IoT Barrier Integration'!B6 -> 22 | E13: ='3. IoT Barrier Integration'!C6 -> 3 | F13: ='3. IoT Barrier Integration'!D6 -> 0 | G13: ='3. IoT Barrier Integration'!E6 -> 0 | H13: ='3. IoT Barrier Integration'!B4 -> 25
B14: 4 | C14: IoT QR Code & Scanner | D14: ='4. IoT QR Code & Scanner'!B6 -> 18 | E14: ='4. IoT QR Code & Scanner'!C6 -> 2 | F14: ='4. IoT QR Code & Scanner'!D6 -> 0 | G14: ='4. IoT QR Code & Scanner'!E6 -> 0 | H14: ='4. IoT QR Code & Scanner'!B4 -> 20
B15: 5 | C15: AI Slot Surveillance & ALPR | D15: ='5. AI Slot Surveillance & ALPR'!B6 -> 30 | E15: ='5. AI Slot Surveillance & ALPR'!C6 -> 1 | F15: ='5. AI Slot Surveillance & ALPR'!D6 -> 0 | G15: ='5. AI Slot Surveillance & ALPR'!E6 -> 0 | H15: ='5. AI Slot Surveillance & ALPR'!B4 -> 31
B16: 6 | C16: 2D Parking Map & Slot Grid | D16: ='6. 2D Parking Map & Slot Grid'!B6 -> 31 | E16: ='6. 2D Parking Map & Slot Grid'!C6 -> 2 | F16: ='6. 2D Parking Map & Slot Grid'!D6 -> 0 | G16: ='6. 2D Parking Map & Slot Grid'!E6 -> 0 | H16: ='6. 2D Parking Map & Slot Grid'!B4 -> 33
B17: 7 | C17: Profile | D17: ='7. Profile '!B7 -> 44 | E17: ='7. Profile '!C7 -> 6 | F17: ='7. Profile '!D7 -> 0 | G17: ='7. Profile '!E7 -> 0
B18: 8 | C18: Account Management | D18: ='8. Account Management'!B8 -> 52 | E18: ='8. Account Management'!C8 -> 0 | F18: ='7. Profile '!D8 -> 0 | G18: ='7. Profile '!E8 -> 0
B19: 9 | C19: Parking Services | D19: ='9. Parking Services'!B6 -> 24
B20: 10 | C20: Ticket Package
B21: 11 | C21: Subscription Management
B22: 12 | C22: VALO AI
C38: Sub total | D38: =SUM(D10:D22) -> 257 | E38: =SUM(E10:E22) -> 21 | F38: =SUM(F10:F22) -> 0 | G38: =SUM(G10:G22) -> 0 | H38: =SUM(H10:H22) -> 152
C40: Test coverage | E40: =(D38+E38)*100/(H38-G38) -> 182.89474 | F40: %
C41: Test successful coverage | E41: =D38*100/(H38-G38) -> 169.07895 | F41: %
C43: HO SY HUNG (HUNGHS) — SPRINT 1 & SPRINT 2
C44: HSH summary uses Round 2 draft statuses; dates/results are retrospective and not historical execution evidence.
B45: 27 | C45: login | D45: ='27. login'!B7 -> 9 | E45: ='27. login'!C7 -> 0 | F45: ='27. login'!D7 -> 0 | G45: ='27. login'!E7 -> 0 | H45: ='27. login'!B4 -> 9
B46: 28 | C46: googleLogin | D46: ='28. googleLogin'!B7 -> 9 | E46: ='28. googleLogin'!C7 -> 0 | F46: ='28. googleLogin'!D7 -> 0 | G46: ='28. googleLogin'!E7 -> 0 | H46: ='28. googleLogin'!B4 -> 9
B47: 29 | C47: forgotResetPassword | D47: ='29. forgotResetPassword'!B7 -> 10 | E47: ='29. forgotResetPassword'!C7 -> 0 | F47: ='29. forgotResetPassword'!D7 -> 0 | G47: ='29. forgotResetPassword'!E7 -> 0 | H47: ='29. forgotResetPassword'!B4 -> 10
B48: 30 | C48: walletService | D48: ='30. walletService'!B7 -> 10 | E48: ='30. walletService'!C7 -> 0 | F48: ='30. walletService'!D7 -> 0 | G48: ='30. walletService'!E7 -> 0 | H48: ='30. walletService'!B4 -> 10
B49: 31 | C49: uploadAvatar | D49: ='31. uploadAvatar'!B7 -> 6 | E49: ='31. uploadAvatar'!C7 -> 0 | F49: ='31. uploadAvatar'!D7 -> 1 | G49: ='31. uploadAvatar'!E7 -> 0 | H49: ='31. uploadAvatar'!B4 -> 7
B50: 32 | C50: violationController | D50: ='32. violationController'!B7 -> 9 | E50: ='32. violationController'!C7 -> 0 | F50: ='32. violationController'!D7 -> 1 | G50: ='32. violationController'!E7 -> 0 | H50: ='32. violationController'!B4 -> 10
B51: 33 | C51: adminActionLog | D51: ='33. adminActionLog'!B7 -> 8 | E51: ='33. adminActionLog'!C7 -> 0 | F51: ='33. adminActionLog'!D7 -> 1 | G51: ='33. adminActionLog'!E7 -> 0 | H51: ='33. adminActionLog'!B4 -> 9
B52: 34 | C52: notificationSocket | D52: ='34. notificationSocket'!B7 -> 6 | E52: ='34. notificationSocket'!C7 -> 0 | F52: ='34. notificationSocket'!D7 -> 4 | G52: ='34. notificationSocket'!E7 -> 0 | H52: ='34. notificationSocket'!B4 -> 10
B53: 35 | C53: checkVIPSubscriptions | D53: ='35. checkVIPSubscriptions'!B7 -> 5 | E53: ='35. checkVIPSubscriptions'!C7 -> 0 | F53: ='35. checkVIPSubscriptions'!D7 -> 4 | G53: ='35. checkVIPSubscriptions'!E7 -> 0 | H53: ='35. checkVIPSubscriptions'!B4 -> 9
B54: 36 | C54: OAuthCallback | D54: ='36. OAuthCallback'!B7 -> 6 | E54: ='36. OAuthCallback'!C7 -> 0 | F54: ='36. OAuthCallback'!D7 -> 0 | G54: ='36. OAuthCallback'!E7 -> 0 | H54: ='36. OAuthCallback'!B4 -> 6
B55: 37 | C55: createBooking | D55: ='37. createBooking'!B7 -> 7 | E55: ='37. createBooking'!C7 -> 0 | F55: ='37. createBooking'!D7 -> 3 | G55: ='37. createBooking'!E7 -> 0 | H55: ='37. createBooking'!B4 -> 10
B56: 38 | C56: checkVietQRStatus | D56: ='38. checkVietQRStatus'!B7 -> 6 | E56: ='38. checkVietQRStatus'!C7 -> 0 | F56: ='38. checkVietQRStatus'!D7 -> 3 | G56: ='38. checkVietQRStatus'!E7 -> 0 | H56: ='38. checkVietQRStatus'!B4 -> 9
B57: 39 | C57: cancelBooking | D57: ='39. cancelBooking'!B7 -> 8 | E57: ='39. cancelBooking'!C7 -> 0 | F57: ='39. cancelBooking'!D7 -> 2 | G57: ='39. cancelBooking'!E7 -> 0 | H57: ='39. cancelBooking'!B4 -> 10
B58: 40 | C58: renewSubscription | D58: ='40. renewSubscription'!B7 -> 6 | E58: ='40. renewSubscription'!C7 -> 0 | F58: ='40. renewSubscription'!D7 -> 4 | G58: ='40. renewSubscription'!E7 -> 0 | H58: ='40. renewSubscription'!B4 -> 10
B59: 41 | C59: saveParkingLayout | D59: ='41. saveParkingLayout'!B7 -> 7 | E59: ='41. saveParkingLayout'!C7 -> 0 | F59: ='41. saveParkingLayout'!D7 -> 3 | G59: ='41. saveParkingLayout'!E7 -> 0 | H59: ='41. saveParkingLayout'!B4 -> 10
B60: 42 | C60: ServiceList | D60: ='42. ServiceList'!B7 -> 8 | E60: ='42. ServiceList'!C7 -> 0 | F60: ='42. ServiceList'!D7 -> 1 | G60: ='42. ServiceList'!E7 -> 0 | H60: ='42. ServiceList'!B4 -> 9
B61: 43 | C61: AuthScreen | D61: ='43. AuthScreen'!B7 -> 5 | E61: ='43. AuthScreen'!C7 -> 0 | F61: ='43. AuthScreen'!D7 -> 4 | G61: ='43. AuthScreen'!E7 -> 0 | H61: ='43. AuthScreen'!B4 -> 9
...

Sheet Test Cases
D1: TEST CASE LIST
B3: Project Name | D3: Developing VALOParking – A smart vehicle automated location organizer using ReactJS, NodeJS, AI YOLOv11 and IoT ESP32.
B4: Project Code | D4: VALO PARKING
B5: Test Environment Setup Description | D5: 1. VALOParking Backend Server: http://localhost:5000 2. VALOParking Frontend Server: http://localhost:5173 3. AI Service: http://localhost:8000 (FastAPI YOLOv11) 4. Database: MongoDB 5. Hardware: ESP32 Barrier Controller, IR Sensors, Webcams, QR Scanners 6. Web browsers: Google Chrome, Microsoft Edge 7. Devices: Kiosk Touchscreen, Laptop, Mobile
B8: No | C8: Function Name | D8: Sheet Name | E8: Description | F8: Pre-Condition
B9: 1 | C9: Kiosk Check-in/Check-out & IoT | D9: Kiosk Check-in & Check-out | E9: Verify complete automated check-in, check-out flows, PayOS payment, and real-time IoT hardware automation (ESP32 Barrier, IR sensors, Socket.io sync). | F9: Backend, Frontend, AI Service, and IoT barrier services are operational.
B10: 2 | C10: Staff Gate & Barrier Control | D10: Staff Gate & Barrier Control | E10: Verify staff portal: multi-camera enumeration, AI blurred plate resolution (confusable pairs & fuzzy match), manual check-in/out, security double-check, cash collection, and Auto-Pilot mode. | F10: Staff authenticated, IoT ESP32 barrier and camera streams online.
B11: 3 | C11: IoT Barrier Integration | D11: IoT Barrier Integration | E11: Verify real-world hardware & firmware integration: ESP32 dual I2C LCD 1602 marquee displays, servo PWM timers, IR auto-calibration & anti-smash safety, 30s open timeout, Python serial bridge (115200 baud), and bidirectional backend synchronization. | F11: ESP32 microcontroller connected via USB, dual servos, dual IR sensors, dual LCDs, Python serial bridge and backend server running.
B12: 4 | C12: IoT QR Code & Scanner | D12: IoT QR Code & Scanner | E12: Verify GM65 USB HID keyboard hardware scanner buffer listener, camera video QR fallback, HMAC-SHA256 signature security, multi-payload resolver (JWT, ObjectId, JSON, Plate), and AI plate cross-check verification. | F12: GM65 hardware scanner connected, Kiosk video camera active, Backend QR crypto service running.
B13: 5 | C13: AI Slot Surveillance & ALPR | D13: AI Slot Surveillance & ALPR | E13: Comprehensive end-to-end testing: YOLOv8-Seg polygon segmentation (27 slanted perspective slots), offline EasyOCR, Gemini 2.5 Flash hybrid fusion, camera misalignment scene validation, diorama plate normalization, 1080p full-res letterboxing compensation, auto-detect floor grid, audio siren alert, 8s background polling, and 1-Click Fast Reassign. | F13: YOLOv8-Seg model loaded, Gemini API key configured, CCTV camera feed online, MongoDB Floor collection active.
B14: 6 | C14: 2D Parking Map Designer & Slot Grid Management | D14: 2D Parking Map & Slot Grid | E14: Verify 2D visual parking lot layout designer, smart grid generator matrix, auto-fill naming algorithms, multi-element alignment/distribution, 50-level undo/redo, VIP entitlement and parked vehicle deletion guards, MongoDB spatial zone mapping, floor switching, and batch slot synchronization. | F14: Backend, MongoDB ParkingFloor and Slot collections, and Frontend Admin builder operational.
B15: 7 | C15: Profile | D15: Profile | E15: Verify customer profile viewing and management, including profile data loading, name/phone update validation, password change, authentication and error handling. | F15: Customer account exists and is active; customer is authenticated with a valid session/access token; VALO backend and database are available.
B16: 8 | C16: Account Management | D16: Account Management | E16: Verify Staff/Admin account management including account listing, search/filter/sort/pagination, account editing, block/unblock, Admin delete, validation and error handling. | F16: Active Staff/Admin account is authenticated with a valid access token; Account Management backend and database are available; target accounts exist where required.
B17: 9 | C17: Parking Services | D17: Parking Services | E17: Verify Admin parking service management including service catalog viewing, create, image upload/replacement, edit, activate/deactivate, delete, validation and authorization. | F17: Active Admin account is authenticated; Parking Service backend/database are available; service/image storage dependencies are available for relevant operations.
B18: 10 | C18: Ticket Package | D18: Ticket Package | E18: Verify Ticket Package functions across guest, customer, staff and admin, including catalog access, Admin package management, package selection, slot eligibility, Wallet/PayOS purchase and membership activation. | F18: Required role/session is available; protected flows use an active authenticated account; package, vehicle, slot, wallet/payment and membership data/services are available as required.
B19: 11 | C19: Subscription | D19: Subscription | E19: Verify Staff/Admin subscription management including subscription list, refresh, search/filter/display and Admin-only membership transfer review, approve/reject and validation. | F19: Active Staff/Admin account is authenticated with a valid access token; subscription data is available; Admin transfer-review dependencies exist for approve/reject scenarios.
B20: 12 | C20: VALO AI | D20: VALO AI | E20: Verify VALO AI for Admin and Staff including Gemini-backed chat, role-based tools, grounded draft creation/approval, notifications, AI actions and deterministic operational monitors. | F20: Active Admin/Staff account is authenticated; VALO AI backend and database are available; Gemini configuration is available for generative chat and relevant monitoring/data sources exist.
... B64: 56 | C64: StaffTicketPackagesScreen | D64: 56. StaffTicketPackagesScreen | E64: Staff read-only ticket-package catalog | F64: StaffTicketPackagesScreen and package API are mocked; Authenticated Staff has read-only package access

Sheet 1. Kiosk Check-in & Check-out
A2: Feature | B2: Kiosk Check-in & Check-out Management | R2: Passed
A3: Test requirement | B3: To verify end-to-end self-service check-in (AI LPR, FastPass QR, slot allocation), check-out (PayOS QR, cash/staff escalation), and real-time IoT hardware automation (ESP32 Barrier, IR sensors, Socket.io sync, emergency override). | R3: Failed
A4: Number of TCs | B4: =COUNTIF(A12:A41, "TC-*") -> 26 | R4: Pending
A5: Testing Round | B5: Passed | C5: Failed | D5: Pending | E5: N/A | R5: N/A
A6: Round 1 | B6: =COUNTIF(F11:F41, B5) -> 19 | C6: =COUNTIF(F11:F41, C5) -> 7 | D6: =COUNTIF(F11:F41, D5) -> 0 | E6: =COUNTIF(F11:F41, E5) -> 0
A7: Round 2 | B7: =COUNTIF(I11:I41, B5) -> 23 | C7: =COUNTIF(I11:I41, C5) -> 3 | D7: =COUNTIF(I11:I41, D5) -> 0 | E7: =COUNTIF(I11:I41, E5) -> 0
A8: Round 3 | B8: =COUNTIF(L11:L41, B5) -> 26 | C8: =COUNTIF(L11:L41, C5) -> 0 | D8: =COUNTIF(L11:L41, D5) -> 0 | E8: =COUNTIF(L11:L41, E5) -> 0
A10: Test Case ID | B10: Test Case Description | C10: Test Case Procedure | D10: Expected Results | E10: Pre-conditions | F10: Round 1 | G10: Test date | H10: Tester | I10: Round 2 | J10: Test date | K10: Tester | L10: Round 3 | M10: Test date | N10: Tester | O10: Note
A11: Function 1: Vehicle Entry & Kiosk Check-In Flow
A12: TC-KIOSK-IN-01 | B12: Check-in attempt when parking capacity is completely full | C12: 1. Vehicle approaches Entry Gate Kiosk. 2. System calls /api/sessions/check-full. 3. Evaluates total occupied slots vs capacity. | D12: - Displays "Parking Full" alert dialog. - "Create Ticket" action is disabled. - Entry barrier remains locked down. | E12: Total available slots in DB = 0 | F12: Passed | G12: 46255 | H12: VyVD | I12: Passed | J12: 46273 | K12: VyVD | L12: Passed | M12: 46297 | N12: VyVD
A13: TC-KIOSK-IN-02 | B13: AI License Plate Recognition on vehicle approach (Happy Path) | C13: 1. Vehicle triggers entry lane camera. 2. Frame captured and sent to YOLOv11 AI service. 3. Optical character recognition extracts plate. | D13: - Plate text extracted with >90% confidence. - Auto-fills plate box on Step 1 screen. - Displays vehicle snapshot preview. | E13: Camera lens unobstructed, standard VN license plate | F13: Passed | G13: 46255 | H13: VyVD | I13: Passed | J13: 46273 | K13: VyVD | L13: Passed | M13: 46297 | N13: VyVD
A14: TC-KIOSK-IN-03 | B14: Manual editing of license plate characters upon OCR error | C14: 1. AI misidentifies blurry character. 2. User taps on plate input field. 3. Edits characters and clicks "Continue". | D14: - Input field allows alphanumeric editing. - System validates format and navigates to Step 2. | E14: User is on Kiosk Step 1 screen | F14: Passed | G14: 46256 | H14: VyVD | I14: Passed | J14: 46274 | K14: VyVD | L14: Passed | M14: 46298 | N14: VyVD
A15: TC-KIOSK-IN-04 | B15: Validation for empty or malformed plate number | C15: 1. Clear the plate input field or enter special characters (!@#). 2. Tap "Continue". | D15: - Displays inline error: "Please enter a valid license plate". - Navigation to next step is blocked. | E15: Kiosk Step 1 active | F15: Passed | G15: 46256 | H15: VyVD | I15: Passed | J15: 46274 | K15: VyVD | L15: Passed | M15: 46298 | N15: VyVD
A16: TC-KIOSK-IN-05 | B16: Rejection of duplicate check-in (Vehicle already inside) | C16: 1. Submit plate number belonging to an active unclosed session. 2. Tap "Continue". | D16: - System rejects entry with alert: "Vehicle already inside parking lot". - No duplicate session created in DB. | E16: Vehicle license plate has active session status in DB | F16: Failed | G16: 46257 | H16: VyVD | I16: Failed | J16: 46275 | K16: VyVD | L16: Passed | M16: 46299 | N16: VyVD | O16: Case-insensitive regex bug fixed in R3 build
A17: TC-KIOSK-IN-06 | B17: FastPass QR check-in for pre-registered / monthly subscription | C17: 1. Driver taps "FastPass / Scan QR". 2. Presents valid FastPass QR to USB scanner. | D17: - System decodes QR token via /api/sessions/kiosk-verify-qr. - Matches registered plate & subscription. - Auto-creates session & sends barrier trigger. | E17: User possesses active subscription QR code | F17: Failed | G17: 46258 | H17: VyVD | I17: Passed | J17: 46276 | K17: VyVD | L17: Passed | M17: 46299 | N17: VyVD | O17: USB scanner raw input buffer delimiter fixed in R2
A18: TC-KIOSK-IN-07 | B18: FastPass check-in with expired, corrupted, or fake QR code | C18: 1. Scan expired or altered QR code on scanner. | D18: - Error dialog: "Invalid or expired FastPass QR code". - Kiosk prompts user to proceed with standard entry ticket. | E18: QR code token is invalid or expired | F18: Passed | G18: 46258 | H18: VyVD | I18: Passed | J18: 46276 | K18: VyVD | L18: Passed | M18: 46299 | N18: VyVD
A19: TC-KIOSK-IN-08 | B19: Vehicle type and parking service selection (Self-Park vs Valet) | C19: 1. On Step 2, select Vehicle Type (Car / Motorbike). 2. Select Parking Mode (Self-Parking / Valet). 3. Tap "Proceed to Confirmation". | D19: - State updates with selected vehicle and mode. - Pricing formula dynamically calculates base rate. | E19: Step 1 validated successfully | F19: Passed | G19: 46259 | H19: VyVD | I19: Passed | J19: 46277 | K19: VyVD | L19: Passed | M19: 46300 | N19: VyVD
A20: TC-KIOSK-IN-09 | B20: Finalize Check-in, assign available slot, and issue QR ticket | C20: 1. Confirm summary on Step 3. 2. Tap "Confirm & Enter". | D20: - Creates new Active session record in MongoDB. - Allocates matching available slot (e.g., A-05). - Renders QR check-in receipt modal on Kiosk. | E20: Available slots exist matching vehicle category | F20: Passed | G20: 46259 | H20: VyVD | I20: Passed | J20: 46277 | K20: VyVD | L20: Passed | M20: 46300 | N20: VyVD
A21: Function 2: Vehicle Exit & Kiosk Check-Out Flow
A22: TC-KIOSK-OUT-01 | B22: Exit camera license plate recognition & session retrieval | C22: 1. Vehicle approaches Kiosk Exit 1. 2. Camera captures plate & calls /api/sessions/kiosk-exit-scan. | D22: - Retrieves active session by plate. - Displays vehicle check-in image, duration, rate, and total fee on invoice screen. | E22: Vehicle has active session in system | F22: Passed | G22: 46260 | H22: VyVD | I22: Passed | J22: 46279 | K22: VyVD | L22: Passed | M22: 46301 | N22: VyVD
A23: TC-KIOSK-OUT-02 | B23: Check-out identification via physical/digital QR ticket scan | C23: 1. Driver holds QR ticket receipt under scanner at Kiosk Out. | D23: - Scanner reads session ID from QR. - Bypasses plate recognition and navigates directly to invoice payment screen. | E23: Valid QR ticket generated from check-in | F23: Passed | G23: 46260 | H23: VyVD | I23: Passed | J23: 46279 | K23: VyVD | L23: Passed | M23: 46301 | N23: VyVD
A24: TC-KIOSK-OUT-03 | B24: Exit process for active monthly subscription (Zero payment) | C24: 1. Scan plate or QR belonging to active monthly plan. | D24: - Total payment due displays 0 VND. - Marks session completed immediately. - Displays "Safe Trip" farewell screen and opens barrier. | E24: Customer has active paid subscription | F24: Passed | G24: 46261 | H24: VyVD | I24: Passed | J24: 46280 | K24: VyVD | L24: Passed | M24: 46303 | N24: VyVD
A25: TC-KIOSK-OUT-04 | B25: Online payment via PayOS dynamic VietQR (Happy Path) | C25: 1. On invoice screen, select "Pay with PayOS VietQR". 2. Kiosk requests PayOS orderCode and displays VietQR. 3. Driver transfers exact amount via mobile banking app. | D25: - PayOS webhook/polling detects status PAID. - Kiosk updates to Success screen in <3 seconds. - Dispatches barrier open signal. | E25: Network connected, PayOS API credentials active | F25: Failed | G25: 46261 | H25: VyVD | I25: Failed | J25: 46281 | K25: VyVD | L25: Passed | M25: 46303 | N25: VyVD | O25: Webhook latency caused checkout timeout; added 2s polling fallback in R3
A26: TC-KIOSK-OUT-05 | B26: Cancel PayOS transaction or QR countdown timeout | C26: 1. Generate VietQR payment code. 2. Tap "Cancel Payment" or let countdown timer expire. | D26: - PayOS order is safely cancelled. - Kiosk safely returns to payment method selection screen without hanging. | E26: VietQR modal currently displayed | F26: Passed | G26: 46262 | H26: VyVD | I26: Passed | J26: 46283 | K26: VyVD | L26: Passed | M26: 46304 | N26: VyVD
A27: TC-KIOSK-OUT-06 | B27: Cash payment assistance / Staff escalation from Kiosk | C27: 1. Driver taps "Pay Cash / Need Assistance". 2. Kiosk dispatches emergency assistance request to staff. | D27: - Kiosk switches to "Waiting for Staff Confirmation" state. - Staff clicks "Confirm Cash Collected" on Staff Dashboard. - Kiosk receives event and completes checkout. | E27: Staff is logged in on Staff Portal | F27: Passed | G27: 46262 | H27: VyVD | I27: Passed | J27: 46283 | K27: VyVD | L27: Passed | M27: 46304 | N27: VyVD
A28: TC-KIOSK-OUT-07 | B28: Unregistered plate / Lost ticket check-out handling | C28: 1. Scan plate not recorded in DB or damaged ticket. | D28: - Kiosk alerts: "No active session found. Please contact staff for assistance". - Exit barrier remains strictly locked. | E28: No active parking session found for given credentials | F28: Passed | G28: 46263 | H28: VyVD | I28: Passed | J28: 46284 | K28: VyVD | L28: Passed | M28: 46305 | N28: VyVD
A29: TC-KIOSK-OUT-08 | B29: Automatic slot de-allocation and capacity increment upon exit | C29: 1. Checkout completes successfully and vehicle departs. | D29: - Session status updates to "completed". - Assigned slot status reverts from "occupied" to "available". - Live capacity incremented by +1 in DB. | E29: Vehicle successfully completed checkout | F29: Failed | G29: 46263 | H29: VyVD | I29: Passed | J29: 46284 | K29: VyVD | L29: Passed | M29: 46305 | N29: VyVD | O29: Fixed MongoDB slot status atomic update concurrency in R2
A30: Function 3: IoT Barrier & Hardware Controller Integration
A31: TC-KIOSK-IOT-01 | B31: Automated Barrier Open trigger on check-in entry (ENTRY_1) | C31: 1. Driver completes Step 3 check-in confirmation. 2. Backend executes triggerBarrierOpen('ENTRY_1'). 3. Checks /api/iot/barrier-status?gate=ENTRY_1. | D31: - open state switches to true. - triggerId generated with current timestamp. - ESP32 servo motor raises gate arm to 90 degrees. | E31: ESP32 controller connected to Wi-Fi / LAN | F31: Passed | G31: 46264 | H31: VyVD | I31: Passed | J31: 46286 | K31: VyVD | L31: Passed | M31: 46306 | N31: VyVD
A32: TC-KIOSK-IOT-02 | B32: Automated Barrier Open trigger on check-out payment success (EXIT_1) | C32: 1. PayOS payment completes or staff approves cash exit. 2. Backend executes triggerBarrierOpen('EXIT_1'). | D32: - open state for EXIT_1 switches to true. - Exit barrier raises gate arm to 90 degrees. - Kiosk displays farewell animation. | E32: Exit barrier controller online | F32: Passed | G32: 46264 | H32: VyVD | I32: Passed | J32: 46286 | K32: VyVD | L32: Passed | M32: 46306 | N32: VyVD
A33: TC-KIOSK-IOT-03 | B33: Infrared (IR) safety sensor anti-smash & auto-close | C33: 1. Barrier opens for vehicle. 2. Vehicle drives through; IR beam is broken. 3. Vehicle fully clears IR beam. | D33: - When IR beam is broken, barrier arm holds position. - Once vehicle clears beam, system triggers auto-close after 3-second safety delay. | E33: IR obstacle sensor calibrated and operational | F33: Failed | G33: 46265 | H33: VyVD | I33: Passed | J33: 46287 | K33: VyVD | L33: Passed | M33: 46307 | N33: VyVD | O33: IR debounce threshold adjusted in ESP32 firmware
A34: TC-KIOSK-IOT-04 | B34: Hold Barrier Mode (Pause barrier & disable IR auto-close) | C34: 1. Staff sends POST /api/iot/hold-barrier with hold: true. 2. Checks barrier response. | D34: - holdOpen state transitions to true. - IR auto-close sensor is disabled. - Barrier remains open indefinitely until release command. | E34: Staff has administrative override privilege | F34: Passed | G34: 46265 | H34: VyVD | I34: Passed | J34: 46287 | K34: VyVD | L34: Passed | M34: 46307 | N34: VyVD
A35: TC-KIOSK-IOT-05 | B35: Force Close Barrier command | C35: 1. Send POST /api/iot/close-barrier for ENTRY_1. 2. Inspect ESP32 servo command. | D35: - open set to false, forceClose set to true. - Barrier immediately lowers to 0-degree position. | E35: Barrier is currently in raised state | F35: Passed | G35: 46266 | H35: VyVD | I35: Passed | J35: 46288 | K35: VyVD | L35: Passed | M35: 46308 | N35: VyVD
A36: Function 4: Real-time Socket Synchronization & Fail-safe
A37: TC-KIOSK-SYNC-01 | B37: Real-time WebSocket event emission on barrier state change | C37: 1. Trigger barrier open or close on Kiosk. 2. Listen for socket event 'gate:barrier_control' on Staff Dashboard. | D37: - WebSocket dispatches updated gateStates JSON instantly (<200ms). - Staff Live Monitor gate status reflects changes in real time. | E37: Socket.io server running and client connected | F37: Passed | G37: 46266 | H37: VyVD | I37: Passed | J37: 46288 | K37: VyVD | L37: Passed | M37: 46308 | N37: VyVD
A38: TC-KIOSK-SYNC-02 | B38: ESP32 offline / network disconnect polling resilience | C38: 1. Disconnect ESP32 from Wi-Fi for 30 seconds. 2. Reconnect ESP32. 3. Poll /api/iot/barrier-status. | D38: - ESP32 reconnects automatically without board restart. - Syncs last triggerId without missing gate open requests. | E38: Hardware test bench connected | F38: Failed | G38: 46267 | H38: VyVD | I38: Failed | J38: 46289 | K38: VyVD | L38: Passed | M38: 46309 | N38: VyVD | O38: Reconnection loop stalled on DNS cache; fixed with exponential backoff in R3
A39: TC-KIOSK-SYNC-03 | B39: AI Service camera stream disconnection recovery | C39: 1. Disconnect entry webcam USB cable during active Kiosk session. 2. Reconnect USB camera. | D39: - Kiosk displays "Camera Reconnecting..." fallback UI. - Auto-recovers video stream without browser page reload. | E39: Kiosk running on touchscreen terminal | F39: Failed | G39: 46267 | H39: VyVD | I39: Passed | J39: 46289 | K39: VyVD | L39: Passed | M39: 46309 | N39: VyVD | O39: Added navigator.mediaDevices.ondevicechange event listener in R2
A40: TC-KIOSK-SYNC-04 | B40: Simultaneous dual-gate check-in and check-out operation | C40: 1. Vehicle checks in at ENTRY_1 while another vehicle checks out at EXIT_1. 2. Trigger both gates simultaneously. | D40: - gateStates.ENTRY_1 and gateStates.EXIT_1 update independently without mutex race conditions. - Both barriers operate concurrently. | E40: Two concurrent sessions active | F40: Passed | G40: 46268 | H40: VyVD | I40: Passed | J40: 46290 | K40: VyVD | L40: Passed | M40: 46309 | N40: VyVD

Sheet 2. Staff Gate & Barrier Control
A2: Feature | B2: Staff Gate & Barrier Control Management | R2: Passed
A3: Test requirement | B3: To verify real-world staff station capabilities: multi-device camera streaming, AI blurred/occluded plate resolution (fuzzy match & Gemini Vision), manual entry check-in, exit security double-check, cash collection confirmation, hardware barrier controls, and autonomous Auto-Pilot mode. | R3: Failed
A4: Number of TCs | B4: =COUNTIF(A12:A33, "TC-*") -> 17 | R4: Pending
A5: Testing Round | B5: Passed | C5: Failed | D5: Pending | E5: N/A | R5: N/A
A6: Round 1 | B6: =COUNTIF(F11:F33, B5) -> 17 | C6: =COUNTIF(F11:F33, C5) -> 0 | D6: =COUNTIF(F11:F33, D5) -> 0 | E6: =COUNTIF(F11:F33, E5) -> 0
A7: Round 2 | B7: =COUNTIF(I11:I33, B5) -> 15 | C7: =COUNTIF(I11:I33, C5) -> 2 | D7: =COUNTIF(I11:I33, D5) -> 0 | E7: =COUNTIF(I11:I33, E5) -> 0
A8: Round 3 | B8: =COUNTIF(L11:L33, B5) -> 17 | C8: =COUNTIF(L11:L33, C5) -> 0 | D8: =COUNTIF(L11:L33, D5) -> 0 | E8: =COUNTIF(L11:L33, E5) -> 0
A10: Test Case ID | B10: Test Case Description | C10: Test Case Procedure | D10: Expected Results | E10: Pre-conditions | F10: Round 1 | G10: Test date | H10: Tester | I10: Round 2 | J10: Test date | K10: Tester | L10: Round 3 | M10: Test date | N10: Tester | O10: Note
A11: Function 1: Multi-Camera Device Enumeration & Live Station Feeds
A12: TC-GATE-CAM-01 | B12: Enumerate connected video input devices and assign to lanes | C12: 1. Connect dual USB webcams to staff station. 2. Open Gate Control page. 3. Call enumerateAllCameras(). | D12: - navigator.mediaDevices detects all videoinput devices. - Auto-assigns Device 1 to valo_entry_cam and Device 2 to valo_exit_cam in localStorage. - Populates dropdown list on both lanes. | E12: Staff logged in with active permissions; cameras connected | F12: Passed | G12: 46256 | H12: VyVD | I12: Passed | J12: 46273 | K12: VyVD | L12: Passed | M12: 46297 | N12: VyVD
A13: TC-GATE-CAM-02 | B13: Switch camera source device dynamically via lane dropdown | C13: 1. Click camera device dropdown on Entry Lane. 2. Select alternative webcam source. | D13: - Stops current video stream tracks. - Starts new MediaStream with exact selected deviceId constraint. - Live feed updates instantly without full page refresh. | E13: At least two distinct webcam devices connected | F13: Passed | G13: 46257 | H13: VyVD | I13: Passed | J13: 46273 | K13: VyVD | L13: Passed | M13: 46297 | N13: VyVD
A14: TC-GATE-CAM-03 | B14: Capture snapshot frame from live video canvas | C14: 1. Click "Capture & AI Scan" on Entry or Exit station. 2. Video frame draws to hidden canvas element. | D14: - Canvas extracts image/jpeg base64 data URL at 0.85 quality. - Snapshot thumbnail renders over video preview with "Live Camera" toggle button. | E14: Camera video stream is currently active | F14: Passed | G14: 46257 | H14: VyVD | I14: Passed | J14: 46274 | K14: VyVD | L14: Passed | M14: 46298 | N14: VyVD
A15: Function 2: AI Blurred / Occluded Plate Resolution Assistant
A16: TC-GATE-AI-01 | B16: Open AI Plate Assistant modal and transfer lane snapshot | C16: 1. Click "AI Blurred Plate Assistant" button under Entry or Exit lane. 2. Observe modal initial state. | D16: - AIPlateResolutionModal opens over screen with backdrop blur. - Passes captured snapshot and current plate string into modal state. - Displays vehicle image preview. | E16: User on Gate Control page with snapshot captured | F16: Passed | G16: 46258 | H16: VyVD | I16: Passed | J16: 46274 | K16: VyVD | L16: Passed | M16: 46298 | N16: VyVD
A17: TC-GATE-AI-02 | B17: Resolve plate using Confusable Pairs & Weighted Levenshtein | C17: 1. Enter blurred plate "51F-88B.99" (B instead of 8). 2. Click "Resolve Plate" calling /api/ai/resolve-unclear-plate. | D17: - Backend plateResolutionService computes weighted distance with CONFUSABLE_PAIRS (8-B cost 0.4). - Fuzzy matches active VIP subscriptions and today's bookings. - Returns candidate plate "51F-888.99" with confidence score and source badge. | E17: Matching booking or registered vehicle exists in database | F17: Passed | G17: 46259 | H17: VyVD | I17: Failed | J17: 46275 | K17: VyVD | L17: Passed | M17: 46299 | N17: VyVD | O17: Passed in R1, but in R2 regex change in normalizeLicensePlate stripped dot separators causing fuzzy distance mismatch; fixed in R3
A18: TC-GATE-AI-03 | B18: Select suggested candidate plate and auto-populate lane form | C18: 1. In AI Resolution modal results, click on candidate card "51F-888.99". 2. Trigger onSelectPlate callback. | D18: - Modal closes. - Selected plate auto-populates entryPlate or exitPlate input box. - Auto-triggers verifyEntryPlate() or lookupExitSession() with verified badge. | E18: Candidate results displayed in modal | F18: Passed | G18: 46259 | H18: VyVD | I18: Passed | J18: 46275 | K18: VyVD | L18: Passed | M18: 46299 | N18: VyVD
A19: Function 3: Staff Assisted Vehicle Check-In & Slot Allocation
A20: TC-GATE-IN-01 | B20: Verify plate and display classification badges (VIP, Booking, Active) | C20: 1. Enter license plate into Entry Lane and blur input. 2. Calls /api/sessions/verify-plate. | D20: - Shows purple badge for Monthly VIP, amber for Pre-Booking, or green for Walk-in. - Displays red error banner: "WARNING: Vehicle currently has an ACTIVE session inside!" if active. | E20: Database has pre-populated test vehicles | F20: Passed | G20: 46260 | H20: VyVD | I20: Passed | J20: 46276 | K20: VyVD | L20: Passed | M20: 46300 | N20: VyVD
A21: TC-GATE-IN-02 | B21: Manual Floor and Slot designation override by staff | C21: 1. Select Floor from dropdown (populated via getAllFloors). 2. Type custom slot code (e.g. "B1-08"). 3. Click "Check-in & Open Barrier". | D21: - Sends POST /api/sessions/kiosk-entry with custom floorId and parkingSlot. - Creates session in DB, executes triggerBarrier('open', 'ENTRY_1'), and resets entry form. | E21: Floor exists with open capacity | F21: Passed | G21: 46260 | H21: VyVD | I21: Passed | J21: 46276 | K21: VyVD | L21: Passed | M21: 46300 | N21: VyVD
A22: TC-GATE-IN-03 | B22: Validation check when clicking Check-In with empty plate | C22: 1. Leave plate input empty. 2. Click "Check-in & Open Barrier". | D22: - Toast notification: "Please enter or scan vehicle license plate". - Check-in API is not dispatched. | E22: Plate input is empty | F22: Passed | G22: 46261 | H22: VyVD | I22: Passed | J22: 46277 | K22: VyVD | L22: Passed | M22: 46300 | N22: VyVD
A23: Function 4: Staff Assisted Vehicle Check-Out & Cash Collection
A24: TC-GATE-OUT-01 | B24: Quick-select vehicle from active sessions dropdown list | C24: 1. In Exit Lane, click "Active vehicles in lot" dropdown. 2. Pick a license plate from active sessions list. | D24: - Immediately populates exitPlate input. - Automatically calls lookupExitSession(plate) and retrieves invoice breakdown. | E24: At least one active session in parking lot | F24: Passed | G24: 46262 | H24: VyVD | I24: Passed | J24: 46279 | K24: VyVD | L24: Passed | M24: 46301 | N24: VyVD
A25: TC-GATE-OUT-02 | B25: Security Double-Check: Side-by-side Entry vs Exit photos | C25: 1. Lookup active exit session. 2. Inspect Security Double-Check panel. | D25: - Displays Check-in photo (from session.entryImage) on the left with check-in time. - Displays current Exit snapshot on the right for visual comparison of plate & vehicle model. | E25: Session has valid entryImage recorded | F25: Passed | G25: 46262 | H25: VyVD | I25: Passed | J25: 46279 | K25: VyVD | L25: Passed | M25: 46301 | N25: VyVD
A26: TC-GATE-OUT-03 | B26: Cash collection confirmation checkbox and checkout dispatch | C26: 1. For fee > 0 VND, tick checkbox "Cash collected directly from customer". 2. Click "Check-out & Open Barrier". | D26: - Sends paymentMethod: "CASH" to /api/sessions/kiosk-checkout. - Backend marks session paymentStatus: "paid". - Triggers triggerBarrier('open', 'EXIT_1') and resets exit form. | E26: Active invoice with positive amount due | F26: Passed | G26: 46263 | H26: VyVD | I26: Passed | J26: 46280 | K26: VyVD | L26: Passed | M26: 46303 | N26: VyVD
A27: TC-GATE-OUT-04 | B27: Checkout button disabled state when no invoice is loaded | C27: 1. Clear exit lane data. 2. Inspect "Check-out & Open Barrier" button state. | D27: - Button has disabled attribute and opacity-50 class. - Clicking button does not trigger any network request. | E27: exitInvoiceData is null | F27: Passed | G27: 46263 | H27: VyVD | I27: Passed | J27: 46280 | K27: VyVD | L27: Passed | M27: 46303 | N27: VyVD
A28: Function 5: Manual Barrier Overrides & Autonomous Auto-Pilot Mode
A29: TC-GATE-OVR-01 | B29: Direct hardware barrier manual control (Open, Hold, Close) | C29: 1. Click "Open Exit Barrier" -> triggers /api/iot/open-barrier. 2. Click "Pause Barrier" -> triggers /api/iot/hold-barrier. 3. Click "Lock Barrier" -> triggers /api/iot/close-barrier. | D29: - API executes successfully with target gate (EXIT_1). - Socket broadcasts gate:barrier_control event. - Barrier status badge toggles between "OPEN" (emerald) and "CLOSED" (red). | E29: Backend IoT routes operational | F29: Passed | G29: 46264 | H29: VyVD | I29: Passed | J29: 46283 | K29: VyVD | L29: Passed | M29: 46304 | N29: VyVD
A30: TC-GATE-OVR-02 | B30: Autonomous Auto-Pilot Mode for VIP & Pre-booking vehicles | C30: 1. Toggle Auto-Pilot switch to ON. 2. Vehicle with Monthly Pass (isMonthly: true) or Pre-booking is scanned at entry lane. | D30: - Auto-pilot automatically calls handleEntryCheckIn(plate, verifyData) without staff manual click. - Opens barrier and logs transaction. | E30: Auto-Pilot toggle active, vehicle has valid subscription | F30: Passed | G30: 46265 | H30: VyVD | I30: Failed | J30: 46284 | K30: VyVD | L30: Passed | M30: 46305 | N30: VyVD | O30: Passed in R1, but in R2 autoPilot state was in closure stale state when interval re-rendered; fixed with functional state ref in R3
A31: TC-GATE-OVR-03 | B31: Auto-Pilot automatic zero-fee exit for monthly subscribers | C31: 1. Toggle Auto-Pilot to ON. 2. Scan exit vehicle with active subscription (totalAmount === 0). | D31: - lookupExitSession detects totalAmount === 0 and autoPilot === true. - Automatically dispatches handleExitCheckOut(data) and raises exit barrier. | E31: Monthly subscriber at exit gate with 0 VND balance due | F31: Passed | G31: 46266 | H31: VyVD | I31: Passed | J31: 46286 | K31: VyVD | L31: Passed | M31: 46306 | N31: VyVD
A32: TC-GATE-OVR-04 | B32: Telemetry polling and ESP32 bridge connection indicator | C32: 1. System runs setInterval(fetchBarrierStatus, 2000). 2. Simulate server/bridge offline. | D32: - When fetch fails, isEspOnline switches to false. - Header badge displays "DISCONNECTED" with red radio icon; displays "ONLINE (115200 BAUD)" with green pulse when connected. | E32: Staff dashboard open | F32: Passed | G32: 46266 | H32: VyVD | I32: Passed | J32: 46286 | K32: VyVD | L32: Passed | M32: 46306 | N32: VyVD

Sheet 3. IoT Barrier Integration
A2: Feature | B2: IoT Dual-Gate Barrier & ESP32 Integration | R2: Passed
A3: Test requirement | B3: To verify end-to-end hardware & firmware integration: ESP32 dual I2C LCD 1602 marquee displays, servo PWM timers, IR auto-calibration & anti-smash safety, 30s open timeout, Python serial bridge (115200 baud), and backend bidirectional synchronization. | R3: Failed
A4: Number of TCs | B4: =COUNTIF(A12:A42, "TC-*") -> 25 | R4: Pending
A5: Testing Round | B5: Passed | C5: Failed | D5: Pending | E5: N/A | R5: N/A
A6: Round 1 | B6: =COUNTIF(F11:F42, B5) -> 22 | C6: =COUNTIF(F11:F42, C5) -> 3 | D6: =COUNTIF(F11:F42, D5) -> 0 | E6: =COUNTIF(F11:F42, E5) -> 0
A7: Round 2 | B7: =COUNTIF(I11:I42, B5) -> 22 | C7: =COUNTIF(I11:I42, C5) -> 3 | D7: =COUNTIF(I11:I42, D5) -> 0 | E7: =COUNTIF(I11:I42, E5) -> 0
A8: Round 3 | B8: =COUNTIF(L11:L42, B5) -> 25 | C8: =COUNTIF(L11:L42, C5) -> 0 | D8: =COUNTIF(L11:L42, D5) -> 0 | E8: =COUNTIF(L11:L42, E5) -> 0
A10: Test Case ID | B10: Test Case Description | C10: Test Case Procedure | D10: Expected Results | E10: Pre-conditions | F10: Round 1 | G10: Test date | H10: Tester | I10: Round 2 | J10: Test date | K10: Tester | L10: Round 3 | M10: Test date | N10: Tester | O10: Note
A11: Function 1: ESP32 Boot, Power Brownout & Dual-Gate Self-Test
A12: TC-IOT-BOOT-01 | B12: Brownout detection disable and initial boot handshake | C12: 1. Power on ESP32 board via USB. 2. Verify RTC_CNTL_BROWN_OUT_REG is set to 0. 3. Monitor UART boot log at 115200 baud. | D12: - Prevents sudden reset loops caused by voltage drop during servo startup. - Serial monitor outputs "ESP32_BARRIER_READY" and header banner. | E12: ESP32 connected to USB port on host terminal | F12: Passed | G12: 46256 | H12: VyVD | I12: Passed | J12: 46273 | K12: VyVD | L12: Passed | M12: 46297 | N12: VyVD
A13: TC-IOT-BOOT-02 | B13: Hardware Self-Test sequence on power-up (0 -> 90 -> 0 degrees) | C13: 1. Connect ESP32 to power. 2. Observe entryGate.selfTest() and exitGate.selfTest() execution. | D13: - Entry servo smoothly sweeps 0 to 90 degrees (15ms delay per 5 deg), holds 600ms, sweeps back to 0 degrees. - Exit servo executes same self-test sequentially after 300ms pause. | E13: Servos attached to PIN 13 (Entry) and PIN 17 (Exit) | F13: Passed | G13: 46256 | H13: VyVD | I13: Passed | J13: 46273 | K13: VyVD | L13: Passed | M13: 46297 | N13: VyVD
A14: TC-IOT-BOOT-03 | B14: ESP32PWM 4-Timer hardware allocation stability | C14: 1. Verify ESP32PWM::allocateTimer(0..3) call in setup(). 2. Attach and sweep both servos simultaneously. | D14: - All 4 hardware timers allocated without PWM frequency clash (50Hz, 500-2400us pulse width). - Servo motors operate without jitter. | E14: ESP32Servo library initialized | F14: Passed | G14: 46257 | H14: VyVD | I14: Passed | J14: 46274 | K14: VyVD | L14: Passed | M14: 46298 | N14: VyVD
A15: Function 2: Dual Independent I2C Bus & LCD 1602 Safe Controllers
A16: TC-IOT-LCD-01 | B16: Independent Dual-I2C wire bus communication (Wire0 vs Wire1) | C16: 1. Initialize I2C_Entry on SDA 21, SCL 22 at 100kHz. 2. Initialize I2C_Exit on SDA 25, SCL 26 at 100kHz. 3. Send text commands to both LCDs. | D16: - Both LCD 1602 displays initialize independently at I2C address 0x27 without bus contention. - Entry and Exit screens display distinct text. | E16: Two separate 1602 LCD modules wired to designated GPIOs | F16: Passed | G16: 46258 | H16: VyVD | I16: Passed | J16: 46274 | K16: VyVD | L16: Passed | M16: 46298 | N16: VyVD
A17: TC-IOT-LCD-02 | B17: SafeI2CLCD disconnection recovery without ESP32 crash | C17: 1. Disconnect I2C SDA wire on Exit LCD while system is running. 2. Send print command through SafeI2CLCD class. | D17: - _wire->endTransmission() returns non-zero error. - _isAvailable flag switches to false. - Code bypasses I2C writes silently without locking I2C bus or freezing MCU. | E17: SafeI2CLCD wrapper active | F17: Failed | G17: 46258 | H17: VyVD | I17: Passed | J17: 46275 | K17: VyVD | L17: Passed | M17: 46299 | N17: VyVD | O17: Wire timeout lockup fixed in SafeI2CLCD error check in R2
A18: TC-IOT-LCD-03 | B18: 250ms Marquee text scrolling on LCD Row 2 | C18: 1. Assign message >16 chars: "WELCOME TO VALO PARKING - HAVE A GREAT DAY!". 2. Observe handleMarquee() over 10 seconds. | D18: - String automatically cycles charPos = (marqueeIndex + i) % msgLen every 250ms. - Text scrolls smoothly across 16-character window without flickering Row 1. | E18: LCD Row 1 static; Row 2 marquee active | F18: Passed | G18: 46259 | H18: VyVD | I18: Passed | J18: 46275 | K18: VyVD | L18: Passed | M18: 46299 | N18: VyVD
A19: TC-IOT-LCD-04 | B19: Display personalized assigned slot on Entry LCD | C19: 1. Send serial command: OPEN|51K-999.88|B2-04|ENTRY_1. 2. Inspect LCD display. | D19: - Line 1 renders: "VAO: 51K-999.88". - Row 2 marquee renders: "XIN CHAO! O DO CUA BAN LA: B2-04 - VUI LONG DO DUNG VI TRI - CHUC MOT NGAY TOT LANH!". | E19: Entry gate open command with slot code | F19: Passed | G19: 46259 | H19: VyVD | I19: Passed | J19: 46276 | K19: VyVD | L19: Passed | M19: 46300 | N19: VyVD
A20: Function 3: Infrared (IR) Sensor Auto-Calibration & Anti-Smash Logic
A21: TC-IOT-IR-01 | B21: Dynamic baseline auto-calibration (Ambient light compensation) | C21: 1. Barrier opens; system waits 800ms to settle mechanical vibration. 2. System reads sensorPin (PIN 19/27) to establish sensorBaseline. | D21: - Successfully samples ambient baseline (0 or 1) depending on active-low/high sensor type. - Detects obstacle when pinVal != sensorBaseline. | E21: IR sensor connected to PIN 19 (Entry) and PIN 27 (Exit) | F21: Passed | G21: 46260 | H21: VyVD | I21: Passed | J21: 46276 | K21: VyVD | L21: Passed | M21: 46300 | N21: VyVD
A22: TC-IOT-IR-02 | B22: Vehicle obstruction detection: Transition to GATE_CAR_UNDER | C22: 1. Barrier is in GATE_OPEN_WAITING state. 2. Vehicle drives under gate, breaking IR beam (pinVal != baseline). | D22: - State immediately transitions to GATE_CAR_UNDER. - Serial outputs: "DA CAT TIA HONG NGOAI: XE DANG QUA CONG!". - Barrier remains held at 90 degrees. | E22: Gate arm in raised 90-degree position | F22: Passed | G22: 46260 | H22: VyVD | I22: Passed | J22: 46277 | K22: VyVD | L22: Passed | M22: 46301 | N22: VyVD
A23: TC-IOT-IR-03 | B23: Anti-Smash protection: Indefinite hold while obstacle remains | C23: 1. Vehicle stops directly under gate, keeping IR beam blocked for 120 seconds. | D23: - clearDetectionStart counter is continuously reset to 0. - Barrier NEVER drops onto vehicle roof regardless of duration held. | E23: Obstacle continuously present in sensor beam | F23: Passed | G23: 46261 | H23: VyVD | I23: Passed | J23: 46277 | K23: VyVD | L23: Passed | M23: 46301 | N23: VyVD
A24: TC-IOT-IR-04 | B24: 80ms debounce filter when vehicle clears IR beam | C24: 1. Vehicle clears sensor beam. 2. Simulate momentary 30ms light reflection glitch. | D24: - System requires uninterrupted clear signal for >= 80ms before advancing to GATE_CAR_PASSED. - Prevents false departure triggers from flickering light. | E24: Vehicle exiting beam zone | F24: Passed | G24: 46261 | H24: VyVD | I24: Failed | J24: 46279 | K24: VyVD | L24: Passed | M24: 46301 | N24: VyVD | O24: Passed in R1, but in R2 reducing debounce from 80ms to 20ms caused fluttering close on truck trailers; reverted to 80ms in R3
A25: TC-IOT-IR-05 | B25: 1.0-second departure countdown and automatic gate lowering | C25: 1. State enters GATE_CAR_PASSED. 2. Keep sensor beam clear for 1000ms. | D25: - After 1000ms delay, system calls close(). - Servo sweeps 90 down to 0 degrees in 5-degree increments (15ms delay). - LCD displays "DANG DONG CONG" then returns to idle banner. | E25: Vehicle has fully cleared sensor beam | F25: Passed | G25: 46262 | H25: VyVD | I25: Passed | J25: 46279 | K25: VyVD | L25: Passed | M25: 46303 | N25: VyVD
A26: TC-IOT-IR-06 | B26: Safety re-open abort: Obstacle re-enters during 1s close countdown | C26: 1. Gate enters GATE_CAR_PASSED. 2. A pedestrian or trailing vehicle breaks IR beam at 500ms into countdown. | D26: - Immediate safety interrupt: reverts state back to GATE_CAR_UNDER. - Serial outputs: "CO VAT CAN TRO LAI -> GIU NGUYEN CONG MO AN TOAN!". - Barrier remains open at 90 degrees. | E26: Countdown timer running (carPassedAt < 1000ms) | F26: Passed | G26: 46262 | H26: VyVD | I26: Passed | J26: 46280 | K26: VyVD | L26: Passed | M26: 46303 | N26: VyVD
A27: TC-IOT-IR-07 | B27: 30-second unattended safety auto-close timeout | C27: 1. Open barrier for vehicle, but driver changes mind and does not enter (beam never broken). 2. Wait 30 seconds. | D27: - After millis() - barrierOpenedAt >= 30000, system triggers safety auto-close. - Serial logs: "HET 30S KHONG CO XE -> TU DONG DONG CONG AN TOAN!". | E27: Barrier open in GATE_OPEN_WAITING state without obstacle | F27: Passed | G27: 46263 | H27: VyVD | I27: Passed | J27: 46280 | K27: VyVD | L27: Passed | M27: 46304 | N27: VyVD
A28: Function 4: Serial Command Protocol Parsing (UART 115200)
A29: TC-IOT-PRT-01 | B29: Parse multi-parameter command: OPEN|plate|slot|gate | C29: 1. Transmit string: OPEN|29A-123.45|A-01|ENTRY_1 over UART. 2. Observe ESP32 token extraction. | D29: - Substring tokenization extracts plate: "29A-123.45", slot: "A-01", gate: "ENTRY_1". - Triggers entryGate.open() with designated slot text. | E29: Serial communication established at 115200 baud | F29: Passed | G29: 46263 | H29: VyVD | I29: Passed | J29: 46281 | K29: VyVD | L29: Passed | M29: 46304 | N29: VyVD
A30: TC-IOT-PRT-02 | B30: Parse standalone CHECKIN and CHECKOUT shorthand commands | C30: 1. Transmit "CHECKIN ". 2. Transmit "CHECKOUT ". | D30: - "CHECKIN" opens Entry gate with default greeting. - "CHECKOUT" opens Exit gate with default farewell message. | E30: ESP32 listening on loop() | F30: Passed | G30: 46264 | H30: VyVD | I30: Passed | J30: 46281 | K30: VyVD | L30: Passed | M30: 46305 | N30: VyVD
A31: TC-IOT-PRT-03 | B31: Parse PAUSE and RESUME maintenance commands | C31: 1. Transmit "PAUSE " or "HOLD ". 2. Inspect gateState. 3. Transmit "RESUME ". | D31: - PAUSE sets state to GATE_HOLD_MAINTENANCE, disables sensor checks, and renders LCD warning. - RESUME restores servo to previous position and reactivates sensor. | E31: Target gate operational | F31: Passed | G31: 46264 | H31: VyVD | I31: Passed | J31: 46283 | K31: VyVD | L31: Passed | M31: 46305 | N31: VyVD
A32: TC-IOT-PRT-04 | B32: Parse FORCE_CLOSE / CLOSE immediate shutdown command | C32: 1. Send "FORCE_CLOSE " while gate is in open or maintenance mode. | D32: - Immediately halts pending routines and lowers servo arm to 0 degrees. - Emits "GATE_CLOSED_GATE_NAME" and "GATE_CLOSED" via UART. | E32: Gate arm in open state | F32: Passed | G32: 46265 | H32: VyVD | I32: Passed | J32: 46283 | K32: VyVD | L32: Passed | M32: 46306 | N32: VyVD
A33: Function 5: Python Bridge Port Discovery, Resiliency & Concurrency
A34: TC-IOT-BRG-01 | B34: Auto-discover ESP32 USB device descriptor in Python Bridge | C34: 1. Connect ESP32 using CH340 or CP210 USB cable. 2. Execute find_esp32_port(). | D34: - serial.tools.list_ports matches device string and returns active COM/tty port without manual user configuration. | E34: Host computer running iot_barrier_bridge.py | F34: Passed | G34: 46266 | H34: VyVD | I34: Passed | J34: 46284 | K34: VyVD | L34: Passed | M34: 46306 | N34: VyVD
A35: TC-IOT-BRG-02 | B35: Automatic UART reconnection loop upon USB cable pull | C35: 1. Disconnect ESP32 USB cable while bridge is actively polling. 2. Reconnect USB cable after 5 seconds. | D35: - Catches SerialException / OSError. - Enters 2-second reconnect loop without terminating process. - Automatically re-establishes connection and resets buffers. | E35: Python bridge running | F35: Failed | G35: 46266 | H35: VyVD | I35: Passed | J35: 46284 | K35: VyVD | L35: Passed | M35: 46307 | N35: VyVD | O35: Unhandled Bad file descriptor crash on macOS fixed in R2
A36: TC-IOT-BRG-03 | B36: Independent dual-gate trigger dispatch in single polling cycle | C36: 1. Update triggerId on both ENTRY_1 and EXIT_1 in backend within same 300ms cycle. 2. Observe serial transmission order. | D36: - Bridge iterates gates dictionary and serializes commands for both gates sequentially. - Both gates actuate without dropping packets. | E36: Both gates triggered simultaneously | F36: Passed | G36: 46267 | H36: VyVD | I36: Failed | J36: 46286 | K36: VyVD | L36: Passed | M36: 46307 | N36: VyVD | O36: Passed in R1, but in R2 last_trigger_ids dictionary shallow copy caused race condition in concurrent updates; fixed in R3
A37: TC-IOT-BRG-04 | B37: Bridge resilience during temporary backend server crash / restart | C37: 1. Stop NodeJS backend for 20 seconds while bridge is active. 2. Restart NodeJS backend. | D37: - Requests exception is caught silently. - Bridge continues serial monitoring and resumes synchronization upon server recovery. | E37: Backend server stopped | F37: Passed | G37: 46267 | H37: VyVD | I37: Passed | J37: 46287 | K37: VyVD | L37: Passed | M37: 46308 | N37: VyVD
A38: Function 6: Bidirectional Hardware-to-Backend State Synchronization
A39: TC-IOT-SYN-01 | B39: Sync Entry Gate closure from ESP32 to Backend /api/iot/close-barrier | C39: 1. Car clears Entry sensor; ESP32 closes gate and prints "GATE_CLOSED_ENTRY_1". 2. Bridge receives serial string. | D39: - Bridge posts to BACKEND_CLOSE_URL with fromBridge=true and gate='ENTRY_1'. - Backend updates ENTRY_1 state.open = false and emits Socket.io event. | E39: Vehicle finished entry pass | F39: Passed | G39: 46268 | H39: VyVD | I39: Passed | J39: 46288 | K39: VyVD | L39: Passed | M39: 46308 | N39: VyVD
A40: TC-IOT-SYN-02 | B40: Sync Exit Gate closure from ESP32 to Backend /api/iot/close-barrier | C40: 1. Car clears Exit sensor; ESP32 closes gate and prints "GATE_CLOSED_EXIT_1". 2. Bridge receives serial string. | D40: - Bridge posts to BACKEND_CLOSE_URL with fromBridge=true and gate='EXIT_1'. - Updates last_trigger_ids['EXIT_1'] with backend response to prevent trigger loop. | E40: Vehicle finished exit pass | F40: Passed | G40: 46268 | H40: VyVD | I40: Passed | J40: 46288 | K40: VyVD | L40: Passed | M40: 46309 | N40: VyVD
A41: TC-IOT-SYN-03 | B41: Initial triggerId synchronization on bridge startup | C41: 1. Start Python bridge while backend already has an active open barrier. 2. Inspect last_trigger_ids initialization. | D41: - If gate should_open on startup, sets last_trigger_ids to -1 to force immediate open command dispatch. - If gate closed, sets last_trigger_ids to current triggerId to avoid duplicate firing. | E41: Backend has active trigger before bridge launches | F41: Failed | G41: 46269 | H41: VyVD | I41: Failed | J41: 46289 | K41: VyVD | L41: Passed | M41: 46309 | N41: VyVD | O41: Initial triggerId=0 caused missed barrier open on bridge startup; resolved in R3 with -1 seed

Sheet 4. IoT QR Code & Scanner
A2: Feature | B2: IoT QR Scanner & Security Verification | R2: Passed
A3: Test requirement | B3: To verify end-to-end QR code scanner hardware and cryptographic verification: GM65 USB HID keyboard scanner listener (rapid keystroke buffer <400ms, debounce 350ms, Enter termination), camera video stream QR scanner fallback, HMAC-SHA256 signature validation (5-minute expiration, one-time use), multi-payload resolution (JWT, MongoDB ObjectId, JSON, Plate string), and AI camera plate cross-check matching. | R3: Failed
A4: Number of TCs | B4: =COUNTIF(A12:A36, "TC-*") -> 20 | R4: Pending
A5: Testing Round | B5: Passed | C5: Failed | D5: Pending | E5: N/A | R5: N/A
A6: Round 1 | B6: =COUNTIF(F11:F36, B5) -> 18 | C6: =COUNTIF(F11:F36, C5) -> 2 | D6: =COUNTIF(F11:F36, D5) -> 0 | E6: =COUNTIF(F11:F36, E5) -> 0
A7: Round 2 | B7: =COUNTIF(I11:I36, B5) -> 17 | C7: =COUNTIF(I11:I36, C5) -> 3 | D7: =COUNTIF(I11:I36, D5) -> 0 | E7: =COUNTIF(I11:I36, E5) -> 0
A8: Round 3 | B8: =COUNTIF(L11:L36, B5) -> 20 | C8: =COUNTIF(L11:L36, C5) -> 0 | D8: =COUNTIF(L11:L36, D5) -> 0 | E8: =COUNTIF(L11:L36, E5) -> 0
A10: Test Case ID | B10: Test Case Description | C10: Test Case Procedure | D10: Expected Results | E10: Pre-conditions | F10: Round 1 | G10: Test date | H10: Tester | I10: Round 2 | J10: Test date | K10: Tester | L10: Round 3 | M10: Test date | N10: Tester | O10: Note
A11: Function 1: GM65 Hardware Barcode/QR Scanner (USB HID Keyboard Hook)
A12: TC-QR-HW-01 | B12: GM65 rapid keystroke buffer capture (<400ms interval) | C12: 1. Scan physical QR code with GM65 barcode/QR scanner module. 2. Hook useQrScannerListener intercepts window keydown events. 3. Verify keystroke interval. | D12: - Scanner emits characters rapidly (<50ms per key). - All characters accumulate in bufferRef without loss. - Prevents buffer clearing when timeDiff <= MAX_INTERVAL_MS (400ms). | E12: GM65 hardware scanner connected via USB in HID POS Keyboard mode | F12: Passed | G12: 46257 | H12: VyVD | I12: Passed | J12: 46273 | K12: VyVD | L12: Passed | M12: 46297 | N12: VyVD
A13: TC-QR-HW-02 | B13: Hardware scanner Enter / Tab key immediate trigger | C13: 1. GM65 scans QR string and appends suffix Enter key code (0x0D). 2. Listen for event.key === "Enter". | D13: - Detects Enter key, prevents default form submit action via event.preventDefault(). - Triggers triggerScan() immediately without waiting for debounce timer. | E13: QR scanner listener hook enabled | F13: Passed | G13: 46257 | H13: VyVD | I13: Passed | J13: 46273 | K13: VyVD | L13: Passed | M13: 46297 | N13: VyVD
A14: TC-QR-HW-03 | B14: Ignore human slow manual keyboard typing | C14: 1. User types characters manually with key interval > 400ms on terminal keyboard. 2. Check bufferRef. | D14: - timeDiff exceeds MAX_INTERVAL_MS (400ms). - Buffer resets automatically. - Does not trigger false positive QR scan on human typing. | E14: Application focused on text input | F14: Passed | G14: 46258 | H14: VyVD | I14: Passed | J14: 46274 | K14: VyVD | L14: Passed | M14: 46298 | N14: VyVD
A15: TC-QR-HW-04 | B15: Fallback 350ms debounce auto-trigger without trailing Enter | C15: 1. Configure scanner to omit carriage return Enter. 2. Scan QR string >= 8 characters. | D15: - Buffer accumulates >= 8 chars. - 350ms debounceTimer fires triggerScan() automatically upon silence. - Logs: "[GM65 Scanner] Full QR Received". | E15: Scanner configured in non-Enter suffix mode | F15: Failed | G15: 46258 | H15: VyVD | I15: Passed | J15: 46274 | K15: VyVD | L15: Passed | M15: 46298 | N15: VyVD | O15: Timer cancellation race condition fixed in R2
A16: TC-QR-HW-05 | B16: Filter modifier keys (Shift, Control, Alt, Meta, CapsLock) | C16: 1. Press Shift + character or CapsLock while scanning. 2. Inspect handleKeyDown evaluation. | D16: - Modifier keys are filtered out without appending text or corrupting the scanner payload string. | E16: Keyboard event listener active | F16: Passed | G16: 46259 | H16: VyVD | I16: Passed | J16: 46275 | K16: VyVD | L16: Passed | M16: 46299 | N16: VyVD
A17: Function 2: Camera Video Stream QR Scanner Fallback (Software Decoder)
A18: TC-QR-CAM-01 | B18: Open KioskQrScannerModal with camera user-facing constraint | C18: 1. Driver clicks "Scan VIP / Booking QR" on touchscreen. 2. Modal renders with Scanner component from @yudiel/react-qr-scanner. | D18: - Modal displays corner brackets overlay with #FFDF00 border styling. - Video stream initializes with scanDelay={300} and facingMode: "user". | E18: Front-facing camera permission available | F18: Passed | G18: 46260 | H18: VyVD | I18: Passed | J18: 46276 | K18: VyVD | L18: Passed | M18: 46300 | N18: VyVD
A19: TC-QR-CAM-02 | B19: Camera permission denial error handling (NotAllowedError) | C19: 1. Deny browser camera permission prompt. 2. Attempt to open scanner modal. | D19: - handleError catches error.name === "NotAllowedError". - Alerts: "Camera access denied! Please allow camera access in your browser settings.". - UI does not crash. | E19: Camera permission set to Block | F19: Passed | G19: 46260 | H19: VyVD | I19: Passed | J19: 46276 | K19: VyVD | L19: Passed | M19: 46300 | N19: VyVD
A20: TC-QR-CAM-03 | B20: Software QR code extraction from live video feed | C20: 1. Present QR code in front of camera lens. 2. Component decodes rawValue at result[0].rawValue. | D20: - Calls handleScan(result) and invokes onScan callback with decoded payload string. - Closes modal automatically upon successful capture. | E20: KioskQrScannerModal open and camera streaming | F20: Passed | G20: 46261 | H20: VyVD | I20: Failed | J20: 46277 | K20: VyVD | L20: Passed | M20: 46301 | N20: VyVD | O20: Passed in R1, but in R2 updating react-qr-scanner package altered result array schema; fixed in R3
A21: Function 3: HMAC-SHA256 Cryptographic Token Security & Anti-Replay
